<robot name="shadowhand_left">

  <!-- Example color/material definitions (same as right hand) -->
  <material name="Blue">
    <color rgba="0.0 0.0 0.8 1.0" />
  </material>
  <material name="Green">
    <color rgba="0.0 0.8 0.0 1.0" />
  </material>
  <material name="Grey">
    <color rgba="0.2 0.2 0.2 1.0" />
  </material>
  <material name="LightGrey">
    <color rgba="0.6 0.6 0.6 1.0" />
  </material>
  <material name="Red">
    <color rgba="0.8 0.0 0.0 1.0" />
  </material>
  <material name="White">
    <color rgba="1.0 1.0 1.0 1.0" />
  </material>

  <!-- ============== WRIST ============== -->
  <link name="wrist_left">
    <inertial>
      <origin rpy="0 0 0" xyz="0 0 0.02" />
      <mass value="0.1" />
      <inertia ixx="0.120" ixy="0.0" ixz="0.0" iyy="0.148" iyz="0.0" izz="0.0438" />
    </inertial>
    <visual>
      <origin rpy="0 0 0" xyz="0 0 0" />
      <geometry>
        <mesh filename="meshes/wrist.dae" scale="0.1 0.1 0.1" />
      </geometry>
      <material name="LightGrey" />
    </visual>
    <collision>
      <origin rpy="0 0 0" xyz="0 0 0" />
      <geometry>
        <box size="0.02 0.02 0.02" />
      </geometry>
    </collision>
  </link>

  <joint name="WRJ1_left" type="revolute">
    <parent link="wrist_left" />
    <child link="palm_left" />
    <origin rpy="0 0 0" xyz="0 0 0.034" />
    <axis xyz="1 0 0" />
    <limit effort="5" lower="-0.78539816339744828" upper="0.6108652381980153" velocity="1.0" />
    <dynamics damping="100.5" />
  </joint>


  <!-- ============== PALM ============== -->
  <link name="palm_left">
    <inertial>
      <origin rpy="0 0 0" xyz="0 0 0" />
      <mass value="0.3" />
      <inertia ixx="0.5" ixy="0.0" ixz="0.0" iyy="0.5" iyz="0.0" izz="0.3" />
    </inertial>
    <visual>
      <origin rpy="0 0 3.14159" xyz="0 0 0" />
      <geometry>
        <!-- created by -1 scale exported in Blender -->
        <mesh filename="meshes/palm_left.obj" scale="0.001 0.001 0.001" />

        <!-- if just set -1 scale here, the normals will be wrong -->
        <!--mesh filename="meshes/palm.obj" scale="-0.001 0.001 0.001" /-->
      </geometry>
      <material name="Grey" />
    </visual>
    <collision>
      <origin rpy="0 0 0" xyz="0 0 0" />
      <geometry>
        <box size="0.05 0.02 0.07" />
      </geometry>
    </collision>
  </link>

  <!-- ============== FIRST (INDEX) FINGER ============== -->
  <link name="ffknuckle_left">
    <inertial>
      <origin rpy="0 0 0" xyz="0 0 0" />
      <mass value="0.008" />
      <inertia ixx="0.0" ixy="0.0" ixz="0.0" iyy="0.1" iyz="0.0" izz="0.0" />
    </inertial>
    <visual>
      <origin rpy="0 0 0" xyz="0 0 0.0005" />
      <geometry>
        <mesh filename="meshes/knuckle.dae" scale="0.1 0.1 0.1" />
      </geometry>
      <material name="LightGrey" />
    </visual>
    <collision>
      <origin rpy="0 0 0" xyz="0 0 0" />
      <geometry>
        <box size="0.005 0.005 0.005" />
      </geometry>
    </collision>
  </link>
  <joint name="FFJ4_left" type="revolute">
    <parent link="palm_left" />
    <child link="ffknuckle_left" />
    <origin rpy="0 0 3.14159" xyz="0.033 0 0.095" />
    <axis xyz="0 -1 0" />
    <limit effort="100" lower="-0.43633231299858238" upper="0.43633231299858238" velocity="1.0" />
    <dynamics damping="50.5" />
  </joint>

  <link name="ffproximal_left">
    <inertial>
      <mass value="0.014" />
      <origin xyz="0 0 0.0225" />
      <inertia ixx="0.1" ixy="0.0" ixz="0.0" iyy="0.1" iyz="0.0" izz="0.0" />
    </inertial>
    <visual>
      <origin rpy="0 0 0" xyz="0 0 0" />
      <geometry>
        <mesh filename="meshes/F3.dae" scale="0.1 0.1 0.1" />
      </geometry>
      <material name="Grey" />
    </visual>
    <collision>
      <origin rpy="0 0 0" xyz="0 0 0.025" />
      <geometry>
        <box size="0.008 0.008 0.04" />
      </geometry>
    </collision>
  </link>
  <joint name="FFJ3_left" type="revolute">
    <parent link="ffknuckle_left" />
    <child link="ffproximal_left" />
    <origin rpy="0 0 0" xyz="0 0 0" />
    <axis xyz="1 0 0" />
    <limit effort="100" lower="0" upper="1.57079632679" velocity="1.0" />
    <dynamics damping="50.5" />
  </joint>

  <link name="ffmiddle_left">
    <inertial>
      <origin rpy="0 0 0" xyz="0 0 0.0125" />
      <mass value="0.012" />
      <inertia ixx="0.1" ixy="0.0" ixz="0.0" iyy="0.1" iyz="0.0" izz="0.0" />
    </inertial>
    <visual>
      <origin rpy="0 0 0" xyz="0 0 0" />
      <geometry>
        <mesh filename="meshes/F2.dae" scale="0.1 0.1 0.1" />
      </geometry>
      <material name="Grey" />
    </visual>
    <collision>
      <origin rpy="0 0 0" xyz="0 0 0.0125" />
      <geometry>
        <box size="0.008 0.008 0.015" />
      </geometry>
    </collision>
  </link>
  <joint name="FFJ2_left" type="revolute">
    <parent link="ffproximal_left" />
    <child link="ffmiddle_left" />
    <origin rpy="0 0 0" xyz="0 0 0.045" />
    <axis xyz="1 0 0" />
    <limit effort="100" lower="0" upper="1.57079632679" velocity="1.0" />
    <dynamics damping="50.5" />
  </joint>

  <link name="ffdistal_left">
    <inertial>
      <mass value="0.010" />
      <origin xyz="0 0 0.013" />
      <inertia ixx="0.1" ixy="0.0" ixz="0.0" iyy="0.1" iyz="0.0" izz="0.0" />
    </inertial>
    <visual>
      <origin rpy="0 0 0" xyz="0 0 0" />
      <geometry>
        <mesh filename="meshes/distal_ellipsoid.dae" scale="0.1 0.1 0.1" />
      </geometry>
      <material name="Grey" />
    </visual>
    <collision>
      <origin rpy="0 0 0" xyz="0 0 0" />
      <geometry>
        <mesh filename="meshes/distal_ellipsoid.dae" scale="0.1 0.1 0.1" />
      </geometry>
    </collision>
  </link>
  <joint name="FFJ1_left" type="revolute">
    <parent link="ffmiddle_left" />
    <child link="ffdistal_left" />
    <origin rpy="0 0 0" xyz="0 0 0.025" />
    <axis xyz="1 0 0" />
    <limit effort="100" lower="0" upper="1.57079632679" velocity="1.0" />
    <dynamics damping="50.5" />
  </joint>

  <link name="fftip_left">
    <inertial>
      <mass value="0.001" />
      <inertia ixx="0.0" ixy="0.0" ixz="0.0" iyy="0.0" iyz="0.0" izz="0.0" />
    </inertial>
  </link>
  <joint name="FFtip_left" type="fixed">
    <parent link="ffdistal_left" />
    <child link="fftip_left" />
    <origin rpy="0 0 0" xyz="0 0 0.026" />
  </joint>


  <!-- ============== MIDDLE FINGER ============== -->
  <link name="mfknuckle_left">
    <inertial>
      <origin rpy="0 0 0" xyz="0 0 0" />
      <mass value="0.008" />
      <inertia ixx="0.0" ixy="0.0" ixz="0.0" iyy="0.1" iyz="0.0" izz="0.0" />
    </inertial>
    <visual>
      <origin rpy="0 0 0" xyz="0 0 0.0005" />
      <geometry>
        <mesh filename="meshes/knuckle.dae" scale="0.1 0.1 0.1" />
      </geometry>
      <material name="LightGrey" />
    </visual>
    <collision>
      <origin rpy="0 0 0" xyz="0 0 0" />
      <geometry>
        <box size="0.005 0.005 0.005" />
      </geometry>
    </collision>
  </link>
  <joint name="MFJ4_left" type="revolute">
    <parent link="palm_left" />
    <child link="mfknuckle_left" />
    <origin rpy="0 0 3.14159" xyz="0.011 0 0.099" />
    <axis xyz="0 -1 0" />
    <limit effort="100" lower="-0.43633231299858238" upper="0.43633231299858238" velocity="1.0" />
    <dynamics damping="50.5" />
  </joint>

  <link name="mfproximal_left">
    <inertial>
      <mass value="0.014" />
      <origin xyz="0 0 0.0225" />
      <inertia ixx="0.1" ixy="0.0" ixz="0.0" iyy="0.1" iyz="0.0" izz="0.0" />
    </inertial>
    <visual>
      <origin rpy="0 0 0" xyz="0 0 0" />
      <geometry>
        <mesh filename="meshes/F3.dae" scale="0.1 0.1 0.1" />
      </geometry>
      <material name="Grey" />
    </visual>
    <collision>
      <origin rpy="0 0 0 " xyz="0 0 0.025" />
      <geometry>
        <box size="0.008 0.008 0.04" />
      </geometry>
    </collision>
  </link>
  <joint name="MFJ3_left" type="revolute">
    <parent link="mfknuckle_left" />
    <child link="mfproximal_left" />
    <origin rpy="0 0 0" xyz="0 0 0" />
    <axis xyz="1 0 0" />
    <limit effort="100" lower="0" upper="1.57079632679" velocity="1.0" />
    <dynamics damping="50.5" />
  </joint>

  <link name="mfmiddle_left">
    <inertial>
      <origin rpy="0 0 0" xyz="0 0 0.0125" />
      <mass value="0.012" />
      <inertia ixx="0.1" ixy="0.0" ixz="0.0" iyy="0.1" iyz="0.0" izz="0.0" />
    </inertial>
    <visual>
      <origin rpy="0 0 0" xyz="0 0 0" />
      <geometry>
        <mesh filename="meshes/F2.dae" scale="0.1 0.1 0.1" />
      </geometry>
      <material name="Grey" />
    </visual>
    <collision>
      <origin rpy="0 0 0" xyz="0 0 0.0125" />
      <geometry>
        <box size="0.008 0.008 0.015" />
      </geometry>
    </collision>
  </link>
  <joint name="MFJ2_left" type="revolute">
    <parent link="mfproximal_left" />
    <child link="mfmiddle_left" />
    <origin rpy="0 0 0" xyz="0 0 0.045" />
    <axis xyz="1 0 0" />
    <limit effort="100" lower="0" upper="1.57079632679" velocity="1.0" />
    <dynamics damping="50.5" />
  </joint>

  <link name="mfdistal_left">
    <inertial>
      <mass value="0.010" />
      <origin xyz="0 0 0.013" />
      <inertia ixx="0.1" ixy="0.0" ixz="0.0" iyy="0.1" iyz="0.0" izz="0.0" />
    </inertial>
    <visual>
      <origin rpy="0 0 0" xyz="0 0 0" />
      <geometry>
        <mesh filename="meshes/F1.dae" scale="0.1 0.1 0.1" />
      </geometry>
      <material name="Grey" />
    </visual>
    <collision>
      <origin rpy="0 0 0" xyz="0 0 0" />
      <geometry>
        <mesh filename="meshes/F1.dae" scale="0.1 0.1 0.1" />
      </geometry>
    </collision>
  </link>
  <joint name="MFJ1_left" type="revolute">
    <parent link="mfmiddle_left" />
    <child link="mfdistal_left" />
    <origin rpy="0 0 0" xyz="0 0 0.025" />
    <axis xyz="1 0 0" />
    <limit effort="100" lower="0" upper="1.57079632679" velocity="1.0" />
    <dynamics damping="50.5" />
  </joint>

  <link name="mftip_left">
    <inertial>
      <mass value="0.001" />
      <inertia ixx="0.0" ixy="0.0" ixz="0.0" iyy="0.0" iyz="0.0" izz="0.0" />
    </inertial>
  </link>
  <joint name="MFtip_left" type="fixed">
    <parent link="mfdistal_left" />
    <child link="mftip_left" />
    <origin rpy="0 0 0" xyz="0 0 0.026" />
  </joint>


  <!-- ============== RING FINGER ============== -->
  <link name="rfknuckle_left">
    <inertial>
      <origin rpy="0 0 0" xyz="0 0 0" />
      <mass value="0.008" />
      <inertia ixx="0.0" ixy="0.0" ixz="0.0" iyy="0.1" iyz="0.0" izz="0.0" />
    </inertial>
    <visual>
      <origin rpy="0 0 0" xyz="0 0 0.0005" />
      <geometry>
        <mesh filename="meshes/knuckle.dae" scale="0.1 0.1 0.1" />
      </geometry>
      <material name="LightGrey" />
    </visual>
    <collision>
      <origin rpy="0 0 0" xyz="0 0 0" />
      <geometry>
        <box size="0.005 0.005 0.005" />
      </geometry>
    </collision>
  </link>
  <joint name="RFJ4_left" type="revolute">
    <parent link="palm_left" />
    <child link="rfknuckle_left" />
    <origin rpy="0 0 3.14159" xyz="-0.011 0 0.095" />
    <axis xyz="0 1 0" />
    <limit effort="100" lower="-0.43633231299858238" upper="0.43633231299858238" velocity="1.0" />
    <dynamics damping="50.5" />
  </joint>

  <link name="rfproximal_left">
    <inertial>
      <mass value="0.014" />
      <origin xyz="0 0 0.0225" />
      <inertia ixx="0.1" ixy="0.0" ixz="0.0" iyy="0.1" iyz="0.0" izz="0.0" />
    </inertial>
    <visual>
      <origin rpy="0 0 0" xyz="0 0 0" />
      <geometry>
        <mesh filename="meshes/F3.dae" scale="0.1 0.1 0.1" />
      </geometry>
      <material name="Grey" />
    </visual>
    <collision>
      <origin rpy="0 0 0 " xyz="0 0 0.025" />
      <geometry>
        <box size="0.008 0.008 0.04" />
      </geometry>
    </collision>
  </link>
  <joint name="RFJ3_left" type="revolute">
    <parent link="rfknuckle_left" />
    <child link="rfproximal_left" />
    <origin rpy="0 0 0" xyz="0 0 0" />
    <axis xyz="1 0 0" />
    <limit effort="100" lower="0" upper="1.57079632679" velocity="1.0" />
    <dynamics damping="50.5" />
  </joint>

  <link name="rfmiddle_left">
    <inertial>
      <origin rpy="0 0 0" xyz="0 0 0.0125" />
      <mass value="0.012" />
      <inertia ixx="0.1" ixy="0.0" ixz="0.0" iyy="0.1" iyz="0.0" izz="0.0" />
    </inertial>
    <visual>
      <origin rpy="0 0 0" xyz="0 0 0" />
      <geometry>
        <mesh filename="meshes/F2.dae" scale="0.1 0.1 0.1" />
      </geometry>
      <material name="Grey" />
    </visual>
    <collision>
      <origin rpy="0 0 0" xyz="0 0 0.0125" />
      <geometry>
        <box size="0.008 0.008 0.015" />
      </geometry>
    </collision>
  </link>
  <joint name="RFJ2_left" type="revolute">
    <parent link="rfproximal_left" />
    <child link="rfmiddle_left" />
    <origin rpy="0 0 0" xyz="0 0 0.045" />
    <axis xyz="1 0 0" />
    <limit effort="100" lower="0" upper="1.57079632679" velocity="1.0" />
    <dynamics damping="50.5" />
  </joint>

  <link name="rfdistal_left">
    <inertial>
      <mass value="0.010" />
      <origin xyz="0 0 0.013" />
      <inertia ixx="0.1" ixy="0.0" ixz="0.0" iyy="0.1" iyz="0.0" izz="0.0" />
    </inertial>
    <visual>
      <origin rpy="0 0 0" xyz="0 0 0" />
      <geometry>
        <mesh filename="meshes/distal_ellipsoid.dae" scale="0.1 0.1 0.1" />
      </geometry>
      <material name="Grey" />
    </visual>
    <collision>
      <origin rpy="0 0 0" xyz="0 0 0" />
      <geometry>
        <mesh filename="meshes/distal_ellipsoid.dae" scale="0.1 0.1 0.1" />
      </geometry>
    </collision>
  </link>
  <joint name="RFJ1_left" type="revolute">
    <parent link="rfmiddle_left" />
    <child link="rfdistal_left" />
    <origin rpy="0 0 0" xyz="0 0 0.025" />
    <axis xyz="1 0 0" />
    <limit effort="100" lower="0" upper="1.57079632679" velocity="1.0" />
    <dynamics damping="50.5" />
  </joint>

  <link name="rftip_left">
    <inertial>
      <mass value="0.001" />
      <inertia ixx="0.0" ixy="0.0" ixz="0.0" iyy="0.0" iyz="0.0" izz="0.0" />
    </inertial>
  </link>
  <joint name="RFtip_left" type="fixed">
    <parent link="rfdistal_left" />
    <child link="rftip_left" />
    <origin rpy="0 0 0" xyz="0 0 0.026" />
  </joint>


  <!-- ============== LITTLE FINGER (lf) ============== -->
  <link name="lfmetacarpal_left">
    <inertial>
      <origin rpy="0 0 0" xyz="0 0 0.04" />
      <mass value="0.075" />
      <inertia ixx="0.1" ixy="0.0" ixz="0.0" iyy="0.1" iyz="0.0" izz="0.1" />
    </inertial>
    <visual>
      <origin rpy="0 0 0" xyz="0 0 0" />
      <geometry>
        <mesh filename="meshes/lf_metacarpal_left.obj" scale="0.001 0.001 0.001" />
        <!--mesh filename="meshes/lfmetacarpal.dae" scale="-0.1 0.1 0.1" /-->
      </geometry>
      <material name="Grey" />
    </visual>
    <collision>
      <origin rpy="0 0 0" xyz="0 0 0.04" />
      <geometry>
        <box size="0.008 0.008 0.03" />
      </geometry>
    </collision>
  </link>
  <joint name="LFJ5_left" type="revolute">
    <parent link="palm_left" />
    <child link="lfmetacarpal_left" />
    <origin rpy="0 0 3.14159" xyz="-0.033 0 0.02071" />
    <axis xyz="0.573576436 0 -0.819152044" />
    <limit effort="100" lower="0" upper="0.69813170079773179" velocity="1.0" />
    <dynamics damping="50.5" />
  </joint>

  <link name="lfknuckle_left">
    <inertial>
      <origin rpy="0 0 0" xyz="0 0 0.06579" />
      <mass value="0.008" />
      <inertia ixx="0.1" ixy="0.0" ixz="0.0" iyy="0.1" iyz="0.0" izz="0.1" />
    </inertial>
    <visual>
      <origin rpy="0 0 0" xyz="0 0 0" />
      <geometry>
        <mesh filename="meshes/knuckle.dae" scale="0.1 0.1 0.1" />
      </geometry>
      <material name="LightGrey" />
    </visual>
    <collision>
      <origin rpy="0 0 0" xyz="0 0 0" />
      <geometry>
        <box size="0.005 0.005 0.005" />
      </geometry>
    </collision>
  </link>
  <joint name="LFJ4_left" type="revolute">
    <parent link="lfmetacarpal_left" />
    <child link="lfknuckle_left" />
    <origin rpy="0 0 0" xyz="0 0 0.06579" />
    <axis xyz="0 1 0" />
    <limit effort="100" lower="-0.43633231299858238" upper="0.43633231299858238" velocity="1.0" />
    <dynamics damping="50.5" />
  </joint>

  <link name="lfproximal_left">
    <inertial>
      <mass value="0.014" />
      <origin xyz="0 0 0.0225" />
      <inertia ixx="0.1" ixy="0.0" ixz="0.0" iyy="0.1" iyz="0.0" izz="0.0" />
    </inertial>
    <visual>
      <origin rpy="0 0 0" xyz="0 0 0" />
      <geometry>
        <mesh filename="meshes/F3.dae" scale="0.1 0.1 0.1" />
      </geometry>
      <material name="Grey" />
    </visual>
    <collision>
      <origin rpy="0 0 0 " xyz="0 0 0.025" />
      <geometry>
        <box size="0.008 0.008 0.04" />
      </geometry>
    </collision>
  </link>
  <joint name="LFJ3_left" type="revolute">
    <parent link="lfknuckle_left" />
    <child link="lfproximal_left" />
    <origin rpy="0 0 0" xyz="0 0 0" />
    <axis xyz="1 0 0" />
    <limit effort="100" lower="0" upper="1.57079632679" velocity="1.0" />
    <dynamics damping="50.5" />
  </joint>

  <link name="lfmiddle_left">
    <inertial>
      <origin rpy="0 0 0" xyz="0 0 0.0125" />
      <mass value="0.012" />
      <inertia ixx="0.1" ixy="0.0" ixz="0.0" iyy="0.1" iyz="0.0" izz="0.0" />
    </inertial>
    <visual>
      <origin rpy="0 0 0" xyz="0 0 0" />
      <geometry>
        <mesh filename="meshes/F2.dae" scale="0.1 0.1 0.1" />
      </geometry>
      <material name="Grey" />
    </visual>
    <collision>
      <origin rpy="0 0 0" xyz="0 0 0.0125" />
      <geometry>
        <box size="0.008 0.008 0.015" />
      </geometry>
    </collision>
  </link>
  <joint name="LFJ2_left" type="revolute">
    <parent link="lfproximal_left" />
    <child link="lfmiddle_left" />
    <origin rpy="0 0 0" xyz="0 0 0.045" />
    <axis xyz="1 0 0" />
    <limit effort="100" lower="0" upper="1.57079632679" velocity="1.0" />
    <dynamics damping="50.5" />
  </joint>

  <link name="lfdistal_left">
    <inertial>
      <mass value="0.010" />
      <origin xyz="0 0 0.013" />
      <inertia ixx="0.1" ixy="0.0" ixz="0.0" iyy="0.1" iyz="0.0" izz="0.0" />
    </inertial>
    <visual>
      <origin rpy="0 0 0" xyz="0 0 0" />
      <geometry>
        <mesh filename="meshes/F1.dae" scale="0.1 0.1 0.1" />
      </geometry>
      <material name="Grey" />
    </visual>
    <collision>
      <origin rpy="0 0 0" xyz="0 0 0" />
      <geometry>
        <mesh filename="meshes/F1.dae" scale="0.1 0.1 0.1" />
      </geometry>
    </collision>
  </link>
  <joint name="LFJ1_left" type="revolute">
    <parent link="lfmiddle_left" />
    <child link="lfdistal_left" />
    <origin rpy="0 0 0" xyz="0 0 0.025" />
    <axis xyz="1 0 0" />
    <limit effort="100" lower="0" upper="1.57079632679" velocity="1.0" />
    <dynamics damping="50.5" />
  </joint>

  <link name="lftip_left">
    <inertial>
      <mass value="0.001" />
      <inertia ixx="0.0" ixy="0.0" ixz="0.0" iyy="0.0" iyz="0.0" izz="0.0" />
    </inertial>
  </link>
  <joint name="LFtip_left" type="fixed">
    <parent link="lfdistal_left" />
    <child link="lftip_left" />
    <origin rpy="0 0 0" xyz="0 0 0.026" />
  </joint>


  <!-- ============== THUMB ============== -->
  <link name="thbase_left">
    <inertial>
      <mass value="0.010" />
      <origin rpy="0 0 0" xyz="0 0 0" />
      <inertia ixx="0.0" ixy="0.0" ixz="0.0" iyy="0.0" iyz="0.0" izz="0.1" />
    </inertial>
    <visual>
      <origin rpy="0 0 0" xyz="0 0 0" />
      <geometry>
        <box size="0.001 0.001 0.001" />
      </geometry>
      <material name="shadow_thbase_material">
        <color rgba="0.5 0.5 0.5 1.0" />
      </material>
    </visual>
    <collision>
      <origin rpy="0 0 0 " xyz="0 0 0" />
      <geometry>
        <box size="0.001 0.001 0.001" />
      </geometry>
    </collision>
  </link>
  <joint name="THJ5_left" type="revolute">
    <parent link="palm_left" />
    <child link="thbase_left" />
    <origin rpy="0 0.785398163397 0" xyz="0.034 0.009 0.029" />
    <axis xyz="0 0 1.0" />
    <limit effort="100" lower="-1.047" upper="1.047" velocity="1.0" />
    <dynamics damping="50.5" />
  </joint>

  <link name="thproximal_left">
    <inertial>
      <mass value="0.016" />
      <origin rpy="0 0 0" xyz="0 0 0.019" />
      <inertia ixx="0.1" ixy="0.0" ixz="0.0" iyy="0.1" iyz="0.0" izz="0.1" />
    </inertial>
    <visual>
      <origin rpy="0 0 0" xyz="0 0 0" />
      <geometry>
        <mesh filename="meshes/TH3_z.dae" scale="0.1 0.1 0.1" />
      </geometry>
      <material name="shadow_thproximal_material">
        <color rgba="0.2 0.2 0.2 1.0" />
      </material>
    </visual>
    <collision>
      <origin rpy="0 0 0" xyz="0 0 0.019" />
      <geometry>
        <box size="0.008 0.008 0.020" />
      </geometry>
    </collision>
  </link>
  <joint name="THJ4_left" type="revolute">
    <parent link="thbase_left" />
    <child link="thproximal_left" />
    <origin rpy="0 0 0" xyz="0 0 0" />
    <axis xyz="-1.0 0 0" />
    <limit effort="100" lower="0" upper="1.222" velocity="1.0" />
    <dynamics damping="50.5" />
  </joint>

  <link name="thhub_left">
    <inertial>
      <mass value="0.002" />
      <origin rpy="0 0 0" xyz="0 0 0" />
      <inertia ixx="0.1" ixy="0.0" ixz="0.0" iyy="0.1" iyz="0.0" izz="0.1" />
    </inertial>
    <visual>
      <origin rpy="0 0 0" xyz="0 0 0" />
      <geometry>
        <box size="0.001 0.001 0.001" />
      </geometry>
      <material name="shadow_thhub_material">
        <color rgba="0.7 0.7 0.7 1.0" />
      </material>
    </visual>
    <collision>
      <origin rpy="0 0 0 " xyz="0 0 0" />
      <geometry>
        <box size="0.001 0.001 0.001" />
      </geometry>
    </collision>
  </link>
  <joint name="THJ3_left" type="revolute">
    <parent link="thproximal_left" />
    <child link="thhub_left" />
    <origin rpy="0 0 0" xyz="0 0 0.038" />
    <axis xyz="1 0 0" />
    <limit effort="100" lower="-0.209" upper="0.209" velocity="1.0" />
    <dynamics damping="50.5" />
  </joint>

  <link name="thmiddle_left">
    <inertial>
      <mass value="0.016" />
      <origin rpy="0 0 0" xyz="0 0 0.016" />
      <inertia ixx="0.1" ixy="0.0" ixz="0.0" iyy="0.1" iyz="0.0" izz="0.1" />
    </inertial>
    <visual>
      <origin rpy="0 0 0" xyz="0 0 0" />
      <geometry>
        <mesh filename="meshes/TH2_z.dae" scale="0.1 0.1 0.1" />
      </geometry>
      <material name="shadow_thmiddle_material">
        <color rgba="0.2 0.2 0.2 1.0" />
      </material>
    </visual>
    <collision>
      <origin rpy="0 0 0 " xyz="0 0 0.016" />
      <geometry>
        <box size="0.008 0.008 0.015" />
      </geometry>
    </collision>
  </link>
  <joint name="THJ2_left" type="revolute">
    <parent link="thhub_left" />
    <child link="thmiddle_left" />
    <origin rpy="0 0 0" xyz="0 0 0" />
    <axis xyz="0 1 0" />
    <limit effort="100" lower="-0.5237" upper="0.5237" velocity="1.0" />
    <dynamics damping="50.5" />
  </joint>

  <link name="thdistal_left">
    <inertial>
      <mass value="0.016" />
      <origin rpy="0 0 0" xyz="0 0 0.01375" />
      <inertia ixx="0.1" ixy="0.0" ixz="0.0" iyy="0.1" iyz="0.0" izz="0.1" />
    </inertial>
    <visual>
      <origin rpy="0 0 0" xyz="0 0.002 0.0025" />
      <geometry>
        <mesh filename="meshes/distal_ellipsoid.dae" scale="0.1 0.1 0.1" />
      </geometry>
      <material name="shadow_thmiddle_material">
        <color rgba="0.2 0.2 0.2 1.0" />
      </material>
    </visual>
    <collision>
      <origin rpy="0 0 0 " xyz="0 0.002 0.0025" />
      <geometry>
        <mesh filename="meshes/distal_ellipsoid.dae" scale="0.1 0.1 0.1" />
      </geometry>
    </collision>
  </link>
  <joint name="THJ1_left" type="revolute">
    <parent link="thmiddle_left" />
    <child link="thdistal_left" />
    <origin rpy="0 0 -1.570796327" xyz="0 0 0.032" />
    <axis xyz="1 0 0" />
    <limit effort="100" lower="-1.571" upper="0" velocity="1.0" />
    <dynamics damping="50.5" />
  </joint>

  <link name="thtip_left">
    <inertial>
      <mass value="0.001" />
      <inertia ixx="0.0" ixy="0.0" ixz="0.0" iyy="0.0" iyz="0.0" izz="0.0" />
    </inertial>
  </link>
  <joint name="thtip_left" type="fixed">
    <parent link="thdistal_left" />
    <child link="thtip_left" />
    <origin rpy="0 0 0" xyz="0 0 0.0275" />
  </joint>

</robot>
